Workbook

Sheet Vessels
A1: Vessel List (30-Vessel Capacity)
A2: Rename Vessel Name cells below (col B) — Tracker sheet updates automatically. Vessel 01 is pre-loaded with sample data from the uploaded template.
A4: Vessel No. | B4: Vessel Name
A5: 1 | B5: Vessel 01
A6: 2 | B6: Vessel 02
A7: 3 | B7: Vessel 03
A8: 4 | B8: Vessel 04
A9: 5 | B9: Vessel 05
A10: 6 | B10: Vessel 06
A11: 7 | B11: Vessel 07
A12: 8 | B12: Vessel 08
A13: 9 | B13: Vessel 09
A14: 10 | B14: Vessel 10
A15: 11 | B15: Vessel 11
A16: 12 | B16: Vessel 12
... A34: 30 | B34: Vessel 30

Sheet Item Master
A1: LSA & FFA Item Master Checklist
A2: 112 tracked items extracted from the source Planning & Arrangement of Services template. This is the checklist applied to every vessel on the Tracker sheet.
A4: # | B4: Category | C4: Item | D4: Interval Label | E4: Interval (Months) | F4: Type
A5: 1 | B5: Life Saving Appliances | C5: Life Boat - Davits | D5: Annual | E5: 12 | F5: Interval-Based
A6: 2 | B6: Life Saving Appliances | C6: Life Boat - Davits | D6: 5 Yearly | E6: 60 | F6: Interval-Based
A7: 3 | B7: Life Saving Appliances | C7: Life Boat - On Load / Off Load Release | D7: Annual | E7: 12 | F7: Interval-Based
A8: 4 | B8: Life Saving Appliances | C8: Life Boat - On Load / Off Load Release | D8: 5 Yearly | E8: 60 | F8: Interval-Based
A9: 5 | B9: Life Saving Appliances | C9: Life Boat - Air Supporting System | D9: Annual | E9: 12 | F9: Interval-Based
A10: 6 | B10: Life Saving Appliances | C10: Life Boat - Air Supporting System | D10: Hydro Test | E10: 60 | F10: Interval-Based
A11: 7 | B11: Life Saving Appliances | C11: Life Boat - Extinguisher | D11: Annual | E11: 12 | F11: Interval-Based
A12: 8 | B12: Life Saving Appliances | C12: Life Boat - Extinguisher | D12: Hydro Test | E12: 60 | F12: Interval-Based
A13: 9 | B13: Life Saving Appliances | C13: Life Boat - Falls | D13: 5 Yearly | E13: 60 | F13: Interval-Based
A14: 10 | B14: Life Saving Appliances | C14: Life Boat - Food Ration | D14: 5 Yearly | E14: 60 | F14: Interval-Based
A15: 11 | B15: Life Saving Appliances | C15: Life Boat - Seasicknes Tablet | D15: 5 Yearly | E15: 60 | F15: Interval-Based
A16: 12 | B16: Life Saving Appliances | C16: Life Boat - First Aid Kit | D16: 5 Yearly | E16: 60 | F16: Interval-Based
... A18: 14 | B18: Life Saving Appliances | C18: Life Boat - FPD | D18: 5 Yearly | E18: 60 | F18: Interval-Based
A19: 15 | B19: Life Saving Appliances | C19: Life Boat - Pyrotechnics | D19: Check Expiry Date | F19: Direct Expiry
A20: 16 | B20: Life Saving Appliances | C20: Rescue Boat - Davits | D20: Annual | E20: 12 | F20: Interval-Based
A21: 17 | B21: Life Saving Appliances | C21: Rescue Boat - Davits | D21: 5 Yearly | E21: 60 | F21: Interval-Based
A22: 18 | B22: Life Saving Appliances | C22: Rescue Boat - On Load / Off Load Release | D22: Annual | E22: 12 | F22: Interval-Based
A23: 19 | B23: Life Saving Appliances | C23: Rescue Boat - On Load / Off Load Release | D23: 5 Yearly | E23: 60 | F23: Interval-Based
A24: 20 | B24: Life Saving Appliances | C24: Rescue Boat - Air Supporting System | D24: Annual | E24: 12 | F24: Interval-Based
A25: 21 | B25: Life Saving Appliances | C25: Rescue Boat - Air Supporting System | D25: Hydro Test | E25: 60 | F25: Interval-Based
A26: 22 | B26: Life Saving Appliances | C26: Rescue Boat - Extinguisher | D26: Annual | E26: 12 | F26: Interval-Based
A27: 23 | B27: Life Saving Appliances | C27: Rescue Boat - Extinguisher | D27: Hydro Test | E27: 60 | F27: Interval-Based
A28: 24 | B28: Life Saving Appliances | C28: Rescue Boat - Falls | D28: 5 Yearly | E28: 60 | F28: Interval-Based
A29: 25 | B29: Life Saving Appliances | C29: Rescue Boat - Food Ration | D29: 5 Yearly | E29: 60 | F29: Interval-Based
A30: 26 | B30: Life Saving Appliances | C30: Rescue Boat - Seasicknes Tablet | D30: 5 Yearly | E30: 60 | F30: Interval-Based
A31: 27 | B31: Life Saving Appliances | C31: Rescue Boat - First Aid Kit | D31: 5 Yearly | E31: 60 | F31: Interval-Based
... A33: 29 | B33: Life Saving Appliances | C33: Rescue Boat - FPD | D33: 5 Yearly | E33: 60 | F33: Interval-Based
A34: 30 | B34: Life Saving Appliances | C34: Rescue Boat - Pyrotechnics | D34: Check Expiry Date | F34: Direct Expiry
A35: 31 | B35: Life Saving Appliances | C35: Life Raft (P) - Life Raft | D35: Annual | E35: 12 | F35: Interval-Based
A36: 32 | B36: Life Saving Appliances | C36: Life Raft (P) - LR HRU | D36: Check Expiry Date | F36: Direct Expiry
A37: 33 | B37: Life Saving Appliances | C37: Life Raft (S) - Life Raft | D37: Annual | E37: 12 | F37: Interval-Based
A38: 34 | B38: Life Saving Appliances | C38: Life Raft (S) - LR HRU | D38: Check Expiry Date | F38: Direct Expiry
A39: 35 | B39: Life Saving Appliances | C39: Fwd Life Raft - LR HRU | D39: Annual | E39: 12 | F39: Interval-Based
A40: 36 | B40: Life Saving Appliances | C40: L J Lights - LR HRU | D40: Check Expiry Date | F40: Direct Expiry
A41: 37 | B41: Life Saving Appliances | C41: SI Lights - LR HRU | D41: Check Expiry Date | F41: Direct Expiry
A42: 38 | B42: Life Saving Appliances | C42: ETA Battery - LR HRU | D42: Check Expiry Date | F42: Direct Expiry
A43: 39 | B43: Life Saving Appliances | C43: EEBD - LR HRU | D43: Annual | E43: 12 | F43: Interval-Based
...

Sheet Tracker
A1: LSA & FFA Service Due Date Tracker
A2: Yellow = due within 2 months | Amber = due within 1 month | Red = overdue. Fill in 'Reference Date' (Last Done, or Expiry Date for Direct-Expiry items) for each vessel; status colors and the Dashboard update automatically.
A4: Vessel | B4: Category | C4: Item | D4: Type | E4: Interval Label | F4: Interval (Months) | G4: Reference Date (Last Done / Expiry) | H4: Next Due Date | I4: Days Until Due | J4: Status | K4: Notes
A5: =Vessels!B5 -> Vessel 01 | B5: Life Saving Appliances | C5: Life Boat - Davits | D5: Interval-Based | E5: Annual | F5: 12 | G5: 46009 | H5: =IFERROR(IF($D5="Manual Review","",IF($G5="","",IF($D5="Direct Expiry",$G5,EDATE($G5,$F5)))),"Check Date") -> 46374 | I5: =IF($H5="","",IF(ISNUMBER($H5),$H5-TODAY(),"")) -> 156 | J5: =IF($D5="Manual Review","Manual Review",IF($G5="","No Data",IF(NOT(ISNUMBER($H5)),"N/A",IF($H5<TODAY(),"Overdue",IF($H5<=TODAY()+30,"Due within 1 Month",IF($H5<=TODAY()+60,"Due within 2 Months","OK")))))) -> OK
A6: =Vessels!B5 -> Vessel 01 | B6: Life Saving Appliances | C6: Life Boat - Davits | D6: Interval-Based | E6: 5 Yearly | F6: 60 | H6: =IFERROR(IF($D6="Manual Review","",IF($G6="","",IF($D6="Direct Expiry",$G6,EDATE($G6,$F6)))),"Check Date") | I6: =IF($H6="","",IF(ISNUMBER($H6),$H6-TODAY(),"")) | J6: =IF($D6="Manual Review","Manual Review",IF($G6="","No Data",IF(NOT(ISNUMBER($H6)),"N/A",IF($H6<TODAY(),"Overdue",IF($H6<=TODAY()+30,"Due within 1 Month",IF($H6<=TODAY()+60,"Due within 2 Months","OK")))))) -> No Data
A7: =Vessels!B5 -> Vessel 01 | B7: Life Saving Appliances | C7: Life Boat - On Load / Off Load Release | D7: Interval-Based | E7: Annual | F7: 12 | G7: 46009 | H7: =IFERROR(IF($D7="Manual Review","",IF($G7="","",IF($D7="Direct Expiry",$G7,EDATE($G7,$F7)))),"Check Date") -> 46374 | I7: =IF($H7="","",IF(ISNUMBER($H7),$H7-TODAY(),"")) -> 156 | J7: =IF($D7="Manual Review","Manual Review",IF($G7="","No Data",IF(NOT(ISNUMBER($H7)),"N/A",IF($H7<TODAY(),"Overdue",IF($H7<=TODAY()+30,"Due within 1 Month",IF($H7<=TODAY()+60,"Due within 2 Months","OK")))))) -> OK
A8: =Vessels!B5 -> Vessel 01 | B8: Life Saving Appliances | C8: Life Boat - On Load / Off Load Release | D8: Interval-Based | E8: 5 Yearly | F8: 60 | H8: =IFERROR(IF($D8="Manual Review","",IF($G8="","",IF($D8="Direct Expiry",$G8,EDATE($G8,$F8)))),"Check Date") | I8: =IF($H8="","",IF(ISNUMBER($H8),$H8-TODAY(),"")) | J8: =IF($D8="Manual Review","Manual Review",IF($G8="","No Data",IF(NOT(ISNUMBER($H8)),"N/A",IF($H8<TODAY(),"Overdue",IF($H8<=TODAY()+30,"Due within 1 Month",IF($H8<=TODAY()+60,"Due within 2 Months","OK")))))) -> No Data
A9: =Vessels!B5 -> Vessel 01 | B9: Life Saving Appliances | C9: Life Boat - Air Supporting System | D9: Interval-Based | E9: Annual | F9: 12 | H9: =IFERROR(IF($D9="Manual Review","",IF($G9="","",IF($D9="Direct Expiry",$G9,EDATE($G9,$F9)))),"Check Date") | I9: =IF($H9="","",IF(ISNUMBER($H9),$H9-TODAY(),"")) | J9: =IF($D9="Manual Review","Manual Review",IF($G9="","No Data",IF(NOT(ISNUMBER($H9)),"N/A",IF($H9<TODAY(),"Overdue",IF($H9<=TODAY()+30,"Due within 1 Month",IF($H9<=TODAY()+60,"Due within 2 Months","OK")))))) -> No Data
A10: =Vessels!B5 -> Vessel 01 | B10: Life Saving Appliances | C10: Life Boat - Air Supporting System | D10: Interval-Based | E10: Hydro Test | F10: 60 | H10: =IFERROR(IF($D10="Manual Review","",IF($G10="","",IF($D10="Direct Expiry",$G10,EDATE($G10,$F10)))),"Check Date") | I10: =IF($H10="","",IF(ISNUMBER($H10),$H10-TODAY(),"")) | J10: =IF($D10="Manual Review","Manual Review",IF($G10="","No Data",IF(NOT(ISNUMBER($H10)),"N/A",IF($H10<TODAY(),"Overdue",IF($H10<=TODAY()+30,"Due within 1 Month",IF($H10<=TODAY()+60,"Due within 2 Months","OK")))))) -> No Data
A11: =Vessels!B5 -> Vessel 01 | B11: Life Saving Appliances | C11: Life Boat - Extinguisher | D11: Interval-Based | E11: Annual | F11: 12 | G11: 45922 | H11: =IFERROR(IF($D11="Manual Review","",IF($G11="","",IF($D11="Direct Expiry",$G11,EDATE($G11,$F11)))),"Check Date") -> 46287 | I11: =IF($H11="","",IF(ISNUMBER($H11),$H11-TODAY(),"")) -> 69 | J11: =IF($D11="Manual Review","Manual Review",IF($G11="","No Data",IF(NOT(ISNUMBER($H11)),"N/A",IF($H11<TODAY(),"Overdue",IF($H11<=TODAY()+30,"Due within 1 Month",IF($H11<=TODAY()+60,"Due within 2 Months","OK")))))) -> OK
A12: =Vessels!B5 -> Vessel 01 | B12: Life Saving Appliances | C12: Life Boat - Extinguisher | D12: Interval-Based | E12: Hydro Test | F12: 60 | H12: =IFERROR(IF($D12="Manual Review","",IF($G12="","",IF($D12="Direct Expiry",$G12,EDATE($G12,$F12)))),"Check Date") | I12: =IF($H12="","",IF(ISNUMBER($H12),$H12-TODAY(),"")) | J12: =IF($D12="Manual Review","Manual Review",IF($G12="","No Data",IF(NOT(ISNUMBER($H12)),"N/A",IF($H12<TODAY(),"Overdue",IF($H12<=TODAY()+30,"Due within 1 Month",IF($H12<=TODAY()+60,"Due within 2 Months","OK")))))) -> No Data
A13: =Vessels!B5 -> Vessel 01 | B13: Life Saving Appliances | C13: Life Boat - Falls | D13: Interval-Based | E13: 5 Yearly | F13: 60 | H13: =IFERROR(IF($D13="Manual Review","",IF($G13="","",IF($D13="Direct Expiry",$G13,EDATE($G13,$F13)))),"Check Date") | I13: =IF($H13="","",IF(ISNUMBER($H13),$H13-TODAY(),"")) | J13: =IF($D13="Manual Review","Manual Review",IF($G13="","No Data",IF(NOT(ISNUMBER($H13)),"N/A",IF($H13<TODAY(),"Overdue",IF($H13<=TODAY()+30,"Due within 1 Month",IF($H13<=TODAY()+60,"Due within 2 Months","OK")))))) -> No Data
A14: =Vessels!B5 -> Vessel 01 | B14: Life Saving Appliances | C14: Life Boat - Food Ration | D14: Interval-Based | E14: 5 Yearly | F14: 60 | G14: 46296 | H14: =IFERROR(IF($D14="Manual Review","",IF($G14="","",IF($D14="Direct Expiry",$G14,EDATE($G14,$F14)))),"Check Date") -> 48122 | I14: =IF($H14="","",IF(ISNUMBER($H14),$H14-TODAY(),"")) -> 1904 | J14: =IF($D14="Manual Review","Manual Review",IF($G14="","No Data",IF(NOT(ISNUMBER($H14)),"N/A",IF($H14<TODAY(),"Overdue",IF($H14<=TODAY()+30,"Due within 1 Month",IF($H14<=TODAY()+60,"Due within 2 Months","OK")))))) -> OK
A15: =Vessels!B5 -> Vessel 01 | B15: Life Saving Appliances | C15: Life Boat - Seasicknes Tablet | D15: Interval-Based | E15: 5 Yearly | F15: 60 | G15: 46235 | H15: =IFERROR(IF($D15="Manual Review","",IF($G15="","",IF($D15="Direct Expiry",$G15,EDATE($G15,$F15)))),"Check Date") -> 48061 | I15: =IF($H15="","",IF(ISNUMBER($H15),$H15-TODAY(),"")) -> 1843 | J15: =IF($D15="Manual Review","Manual Review",IF($G15="","No Data",IF(NOT(ISNUMBER($H15)),"N/A",IF($H15<TODAY(),"Overdue",IF($H15<=TODAY()+30,"Due within 1 Month",IF($H15<=TODAY()+60,"Due within 2 Months","OK")))))) -> OK
A16: =Vessels!B5 -> Vessel 01 | B16: Life Saving Appliances | C16: Life Boat - First Aid Kit | D16: Interval-Based | E16: 5 Yearly | F16: 60 | G16: 47119 | H16: =IFERROR(IF($D16="Manual Review","",IF($G16="","",IF($D16="Direct Expiry",$G16,EDATE($G16,$F16)))),"Check Date") -> 48945 | I16: =IF($H16="","",IF(ISNUMBER($H16),$H16-TODAY(),"")) -> 2727 | J16: =IF($D16="Manual Review","Manual Review",IF($G16="","No Data",IF(NOT(ISNUMBER($H16)),"N/A",IF($H16<TODAY(),"Overdue",IF($H16<=TODAY()+30,"Due within 1 Month",IF($H16<=TODAY()+60,"Due within 2 Months","OK")))))) -> OK
A17: =Vessels!B5 -> Vessel 01 | B17: Life Saving Appliances | C17: Life Boat - Water | D17: Interval-Based | E17: 5 Yearly | F17: 60 | G17: 46357 | H17: =IFERROR(IF($D17="Manual Review","",IF($G17="","",IF($D17="Direct Expiry",$G17,EDATE($G17,$F17)))),"Check Date") -> 48183 | I17: =IF($H17="","",IF(ISNUMBER($H17),$H17-TODAY(),"")) -> 1965 | J17: =IF($D17="Manual Review","Manual Review",IF($G17="","No Data",IF(NOT(ISNUMBER($H17)),"N/A",IF($H17<TODAY(),"Overdue",IF($H17<=TODAY()+30,"Due within 1 Month",IF($H17<=TODAY()+60,"Due within 2 Months","OK")))))) -> OK
A18: =Vessels!B5 -> Vessel 01 | B18: Life Saving Appliances | C18: Life Boat - FPD | D18: Interval-Based | E18: 5 Yearly | F18: 60 | H18: =IFERROR(IF($D18="Manual Review","",IF($G18="","",IF($D18="Direct Expiry",$G18,EDATE($G18,$F18)))),"Check Date") | I18: =IF($H18="","",IF(ISNUMBER($H18),$H18-TODAY(),"")) | J18: =IF($D18="Manual Review","Manual Review",IF($G18="","No Data",IF(NOT(ISNUMBER($H18)),"N/A",IF($H18<TODAY(),"Overdue",IF($H18<=TODAY()+30,"Due within 1 Month",IF($H18<=TODAY()+60,"Due within 2 Months","OK")))))) -> No Data
A19: =Vessels!B5 -> Vessel 01 | B19: Life Saving Appliances | C19: Life Boat - Pyrotechnics | D19: Direct Expiry | E19: Check Expiry Date | G19: 46966 | H19: =IFERROR(IF($D19="Manual Review","",IF($G19="","",IF($D19="Direct Expiry",$G19,EDATE($G19,$F19)))),"Check Date") -> 46966 | I19: =IF($H19="","",IF(ISNUMBER($H19),$H19-TODAY(),"")) -> 748 | J19: =IF($D19="Manual Review","Manual Review",IF($G19="","No Data",IF(NOT(ISNUMBER($H19)),"N/A",IF($H19<TODAY(),"Overdue",IF($H19<=TODAY()+30,"Due within 1 Month",IF($H19<=TODAY()+60,"Due within 2 Months","OK")))))) -> OK
A20: =Vessels!B5 -> Vessel 01 | B20: Life Saving Appliances | C20: Rescue Boat - Davits | D20: Interval-Based | E20: Annual | F20: 12 | G20: 46009 | H20: =IFERROR(IF($D20="Manual Review","",IF($G20="","",IF($D20="Direct Expiry",$G20,EDATE($G20,$F20)))),"Check Date") -> 46374 | I20: =IF($H20="","",IF(ISNUMBER($H20),$H20-TODAY(),"")) -> 156 | J20: =IF($D20="Manual Review","Manual Review",IF($G20="","No Data",IF(NOT(ISNUMBER($H20)),"N/A",IF($H20<TODAY(),"Overdue",IF($H20<=TODAY()+30,"Due within 1 Month",IF($H20<=TODAY()+60,"Due within 2 Months","OK")))))) -> OK
A21: =Vessels!B5 -> Vessel 01 | B21: Life Saving Appliances | C21: Rescue Boat - Davits | D21: Interval-Based | E21: 5 Yearly | F21: 60 | H21: =IFERROR(IF($D21="Manual Review","",IF($G21="","",IF($D21="Direct Expiry",$G21,EDATE($G21,$F21)))),"Check Date") | I21: =IF($H21="","",IF(ISNUMBER($H21),$H21-TODAY(),"")) | J21: =IF($D21="Manual Review","Manual Review",IF($G21="","No Data",IF(NOT(ISNUMBER($H21)),"N/A",IF($H21<TODAY(),"Overdue",IF($H21<=TODAY()+30,"Due within 1 Month",IF($H21<=TODAY()+60,"Due within 2 Months","OK")))))) -> No Data
A22: =Vessels!B5 -> Vessel 01 | B22: Life Saving Appliances | C22: Rescue Boat - On Load / Off Load Release | D22: Interval-Based | E22: Annual | F22: 12 | G22: 46009 | H22: =IFERROR(IF($D22="Manual Review","",IF($G22="","",IF($D22="Direct Expiry",$G22,EDATE($G22,$F22)))),"Check Date") -> 46374 | I22: =IF($H22="","",IF(ISNUMBER($H22),$H22-TODAY(),"")) -> 156 | J22: =IF($D22="Manual Review","Manual Review",IF($G22="","No Data",IF(NOT(ISNUMBER($H22)),"N/A",IF($H22<TODAY(),"Overdue",IF($H22<=TODAY()+30,"Due within 1 Month",IF($H22<=TODAY()+60,"Due within 2 Months","OK")))))) -> OK
A23: =Vessels!B5 -> Vessel 01 | B23: Life Saving Appliances | C23: Rescue Boat - On Load / Off Load Release | D23: Interval-Based | E23: 5 Yearly | F23: 60 | H23: =IFERROR(IF($D23="Manual Review","",IF($G23="","",IF($D23="Direct Expiry",$G23,EDATE($G23,$F23)))),"Check Date") | I23: =IF($H23="","",IF(ISNUMBER($H23),$H23-TODAY(),"")) | J23: =IF($D23="Manual Review","Manual Review",IF($G23="","No Data",IF(NOT(ISNUMBER($H23)),"N/A",IF($H23<TODAY(),"Overdue",IF($H23<=TODAY()+30,"Due within 1 Month",IF($H23<=TODAY()+60,"Due within 2 Months","OK")))))) -> No Data
A24: =Vessels!B5 -> Vessel 01 | B24: Life Saving Appliances | C24: Rescue Boat - Air Supporting System | D24: Interval-Based | E24: Annual | F24: 12 | H24: =IFERROR(IF($D24="Manual Review","",IF($G24="","",IF($D24="Direct Expiry",$G24,EDATE($G24,$F24)))),"Check Date") | I24: =IF($H24="","",IF(ISNUMBER($H24),$H24-TODAY(),"")) | J24: =IF($D24="Manual Review","Manual Review",IF($G24="","No Data",IF(NOT(ISNUMBER($H24)),"N/A",IF($H24<TODAY(),"Overdue",IF($H24<=TODAY()+30,"Due within 1 Month",IF($H24<=TODAY()+60,"Due within 2 Months","OK")))))) -> No Data
A25: =Vessels!B5 -> Vessel 01 | B25: Life Saving Appliances | C25: Rescue Boat - Air Supporting System | D25: Interval-Based | E25: Hydro Test | F25: 60 | H25: =IFERROR(IF($D25="Manual Review","",IF($G25="","",IF($D25="Direct Expiry",$G25,EDATE($G25,$F25)))),"Check Date") | I25: =IF($H25="","",IF(ISNUMBER($H25),$H25-TODAY(),"")) | J25: =IF($D25="Manual Review","Manual Review",IF($G25="","No Data",IF(NOT(ISNUMBER($H25)),"N/A",IF($H25<TODAY(),"Overdue",IF($H25<=TODAY()+30,"Due within 1 Month",IF($H25<=TODAY()+60,"Due within 2 Months","OK")))))) -> No Data
A26: =Vessels!B5 -> Vessel 01 | B26: Life Saving Appliances | C26: Rescue Boat - Extinguisher | D26: Interval-Based | E26: Annual | F26: 12 | G26: 45922 | H26: =IFERROR(IF($D26="Manual Review","",IF($G26="","",IF($D26="Direct Expiry",$G26,EDATE($G26,$F26)))),"Check Date") -> 46287 | I26: =IF($H26="","",IF(ISNUMBER($H26),$H26-TODAY(),"")) -> 69 | J26: =IF($D26="Manual Review","Manual Review",IF($G26="","No Data",IF(NOT(ISNUMBER($H26)),"N/A",IF($H26<TODAY(),"Overdue",IF($H26<=TODAY()+30,"Due within 1 Month",IF($H26<=TODAY()+60,"Due within 2 Months","OK")))))) -> OK
A27: =Vessels!B5 -> Vessel 01 | B27: Life Saving Appliances | C27: Rescue Boat - Extinguisher | D27: Interval-Based | E27: Hydro Test | F27: 60 | H27: =IFERROR(IF($D27="Manual Review","",IF($G27="","",IF($D27="Direct Expiry",$G27,EDATE($G27,$F27)))),"Check Date") | I27: =IF($H27="","",IF(ISNUMBER($H27),$H27-TODAY(),"")) | J27: =IF($D27="Manual Review","Manual Review",IF($G27="","No Data",IF(NOT(ISNUMBER($H27)),"N/A",IF($H27<TODAY(),"Overdue",IF($H27<=TODAY()+30,"Due within 1 Month",IF($H27<=TODAY()+60,"Due within 2 Months","OK")))))) -> No Data
A28: =Vessels!B5 -> Vessel 01 | B28: Life Saving Appliances | C28: Rescue Boat - Falls | D28: Interval-Based | E28: 5 Yearly | F28: 60 | H28: =IFERROR(IF($D28="Manual Review","",IF($G28="","",IF($D28="Direct Expiry",$G28,EDATE($G28,$F28)))),"Check Date") | I28: =IF($H28="","",IF(ISNUMBER($H28),$H28-TODAY(),"")) | J28: =IF($D28="Manual Review","Manual Review",IF($G28="","No Data",IF(NOT(ISNUMBER($H28)),"N/A",IF($H28<TODAY(),"Overdue",IF($H28<=TODAY()+30,"Due within 1 Month",IF($H28<=TODAY()+60,"Due within 2 Months","OK")))))) -> No Data
A29: =Vessels!B5 -> Vessel 01 | B29: Life Saving Appliances | C29: Rescue Boat - Food Ration | D29: Interval-Based | E29: 5 Yearly | F29: 60 | H29: =IFERROR(IF($D29="Manual Review","",IF($G29="","",IF($D29="Direct Expiry",$G29,EDATE($G29,$F29)))),"Check Date") | I29: =IF($H29="","",IF(ISNUMBER($H29),$H29-TODAY(),"")) | J29: =IF($D29="Manual Review","Manual Review",IF($G29="","No Data",IF(NOT(ISNUMBER($H29)),"N/A",IF($H29<TODAY(),"Overdue",IF($H29<=TODAY()+30,"Due within 1 Month",IF($H29<=TODAY()+60,"Due within 2 Months","OK")))))) -> No Data
A30: =Vessels!B5 -> Vessel 01 | B30: Life Saving Appliances | C30: Rescue Boat - Seasicknes Tablet | D30: Interval-Based | E30: 5 Yearly | F30: 60 | H30: =IFERROR(IF($D30="Manual Review","",IF($G30="","",IF($D30="Direct Expiry",$G30,EDATE($G30,$F30)))),"Check Date") | I30: =IF($H30="","",IF(ISNUMBER($H30),$H30-TODAY(),"")) | J30: =IF($D30="Manual Review","Manual Review",IF($G30="","No Data",IF(NOT(ISNUMBER($H30)),"N/A",IF($H30<TODAY(),"Overdue",IF($H30<=TODAY()+30,"Due within 1 Month",IF($H30<=TODAY()+60,"Due within 2 Months","OK")))))) -> No Data
A31: =Vessels!B5 -> Vessel 01 | B31: Life Saving Appliances | C31: Rescue Boat - First Aid Kit | D31: Interval-Based | E31: 5 Yearly | F31: 60 | G31: 47119 | H31: =IFERROR(IF($D31="Manual Review","",IF($G31="","",IF($D31="Direct Expiry",$G31,EDATE($G31,$F31)))),"Check Date") -> 48945 | I31: =IF($H31="","",IF(ISNUMBER($H31),$H31-TODAY(),"")) -> 2727 | J31: =IF($D31="Manual Review","Manual Review",IF($G31="","No Data",IF(NOT(ISNUMBER($H31)),"N/A",IF($H31<TODAY(),"Overdue",IF($H31<=TODAY()+30,"Due within 1 Month",IF($H31<=TODAY()+60,"Due within 2 Months","OK")))))) -> OK
A32: =Vessels!B5 -> Vessel 01 | B32: Life Saving Appliances | C32: Rescue Boat - Water | D32: Interval-Based | E32: 5 Yearly | F32: 60 | H32: =IFERROR(IF($D32="Manual Review","",IF($G32="","",IF($D32="Direct Expiry",$G32,EDATE($G32,$F32)))),"Check Date") | I32: =IF($H32="","",IF(ISNUMBER($H32),$H32-TODAY(),"")) | J32: =IF($D32="Manual Review","Manual Review",IF($G32="","No Data",IF(NOT(ISNUMBER($H32)),"N/A",IF($H32<TODAY(),"Overdue",IF($H32<=TODAY()+30,"Due within 1 Month",IF($H32<=TODAY()+60,"Due within 2 Months","OK")))))) -> No Data
A33: =Vessels!B5 -> Vessel 01 | B33: Life Saving Appliances | C33: Rescue Boat - FPD | D33: Interval-Based | E33: 5 Yearly | F33: 60 | H33: =IFERROR(IF($D33="Manual Review","",IF($G33="","",IF($D33="Direct Expiry",$G33,EDATE($G33,$F33)))),"Check Date") | I33: =IF($H33="","",IF(ISNUMBER($H33),$H33-TODAY(),"")) | J33: =IF($D33="Manual Review","Manual Review",IF($G33="","No Data",IF(NOT(ISNUMBER($H33)),"N/A",IF($H33<TODAY(),"Overdue",IF($H33<=TODAY()+30,"Due within 1 Month",IF($H33<=TODAY()+60,"Due within 2 Months","OK")))))) -> No Data
A34: =Vessels!B5 -> Vessel 01 | B34: Life Saving Appliances | C34: Rescue Boat - Pyrotechnics | D34: Direct Expiry | E34: Check Expiry Date | H34: =IFERROR(IF($D34="Manual Review","",IF($G34="","",IF($D34="Direct Expiry",$G34,EDATE($G34,$F34)))),"Check Date") | I34: =IF($H34="","",IF(ISNUMBER($H34),$H34-TODAY(),"")) | J34: =IF($D34="Manual Review","Manual Review",IF($G34="","No Data",IF(NOT(ISNUMBER($H34)),"N/A",IF($H34<TODAY(),"Overdue",IF($H34<=TODAY()+30,"Due within 1 Month",IF($H34<=TODAY()+60,"Due within 2 Months","OK")))))) -> No Data
A35: =Vessels!B5 -> Vessel 01 | B35: Life Saving Appliances | C35: Life Raft (P) - Life Raft | D35: Interval-Based | E35: Annual | F35: 12 | G35: 45812 | H35: =IFERROR(IF($D35="Manual Review","",IF($G35="","",IF($D35="Direct Expiry",$G35,EDATE($G35,$F35)))),"Check Date") -> 46177 | I35: =IF($H35="","",IF(ISNUMBER($H35),$H35-TODAY(),"")) -> -41 | J35: =IF($D35="Manual Review","Manual Review",IF($G35="","No Data",IF(NOT(ISNUMBER($H35)),"N/A",IF($H35<TODAY(),"Overdue",IF($H35<=TODAY()+30,"Due within 1 Month",IF($H35<=TODAY()+60,"Due within 2 Months","OK")))))) -> Overdue
A36: =Vessels!B5 -> Vessel 01 | B36: Life Saving Appliances | C36: Life Raft (P) - LR HRU | D36: Direct Expiry | E36: Check Expiry Date | G36: 46174 | H36: =IFERROR(IF($D36="Manual Review","",IF($G36="","",IF($D36="Direct Expiry",$G36,EDATE($G36,$F36)))),"Check Date") -> 46174 | I36: =IF($H36="","",IF(ISNUMBER($H36),$H36-TODAY(),"")) -> -44 | J36: =IF($D36="Manual Review","Manual Review",IF($G36="","No Data",IF(NOT(ISNUMBER($H36)),"N/A",IF($H36<TODAY(),"Overdue",IF($H36<=TODAY()+30,"Due within 1 Month",IF($H36<=TODAY()+60,"Due within 2 Months","OK")))))) -> Overdue
A37: =Vessels!B5 -> Vessel 01 | B37: Life Saving Appliances | C37: Life Raft (S) - Life Raft | D37: Interval-Based | E37: Annual | F37: 12 | G37: 45812 | H37: =IFERROR(IF($D37="Manual Review","",IF($G37="","",IF($D37="Direct Expiry",$G37,EDATE($G37,$F37)))),"Check Date") -> 46177 | I37: =IF($H37="","",IF(ISNUMBER($H37),$H37-TODAY(),"")) -> -41 | J37: =IF($D37="Manual Review","Manual Review",IF($G37="","No Data",IF(NOT(ISNUMBER($H37)),"N/A",IF($H37<TODAY(),"Overdue",IF($H37<=TODAY()+30,"Due within 1 Month",IF($H37<=TODAY()+60,"Due within 2 Months","OK")))))) -> Overdue
A38: =Vessels!B5 -> Vessel 01 | B38: Life Saving Appliances | C38: Life Raft (S) - LR HRU | D38: Direct Expiry | E38: Check Expiry Date | G38: 46174 | H38: =IFERROR(IF($D38="Manual Review","",IF($G38="","",IF($D38="Direct Expiry",$G38,EDATE($G38,$F38)))),"Check Date") -> 46174 | I38: =IF($H38="","",IF(ISNUMBER($H38),$H38-TODAY(),"")) -> -44 | J38: =IF($D38="Manual Review","Manual Review",IF($G38="","No Data",IF(NOT(ISNUMBER($H38)),"N/A",IF($H38<TODAY(),"Overdue",IF($H38<=TODAY()+30,"Due within 1 Month",IF($H38<=TODAY()+60,"Due within 2 Months","OK")))))) -> Overdue
A39: =Vessels!B5 -> Vessel 01 | B39: Life Saving Appliances | C39: Fwd Life Raft - LR HRU | D39: Interval-Based | E39: Annual | F39: 12 | G39: 45812 | H39: =IFERROR(IF($D39="Manual Review","",IF($G39="","",IF($D39="Direct Expiry",$G39,EDATE($G39,$F39)))),"Check Date") -> 46177 | I39: =IF($H39="","",IF(ISNUMBER($H39),$H39-TODAY(),"")) -> -41 | J39: =IF($D39="Manual Review","Manual Review",IF($G39="","No Data",IF(NOT(ISNUMBER($H39)),"N/A",IF($H39<TODAY(),"Overdue",IF($H39<=TODAY()+30,"Due within 1 Month",IF($H39<=TODAY()+60,"Due within 2 Months","OK")))))) -> Overdue
A40: =Vessels!B5 -> Vessel 01 | B40: Life Saving Appliances | C40: L J Lights - LR HRU | D40: Direct Expiry | E40: Check Expiry Date | H40: =IFERROR(IF($D40="Manual Review","",IF($G40="","",IF($D40="Direct Expiry",$G40,EDATE($G40,$F40)))),"Check Date") | I40: =IF($H40="","",IF(ISNUMBER($H40),$H40-TODAY(),"")) | J40: =IF($D40="Manual Review","Manual Review",IF($G40="","No Data",IF(NOT(ISNUMBER($H40)),"N/A",IF($H40<TODAY(),"Overdue",IF($H40<=TODAY()+30,"Due within 1 Month",IF($H40<=TODAY()+60,"Due within 2 Months","OK")))))) -> No Data
A41: =Vessels!B5 -> Vessel 01 | B41: Life Saving Appliances | C41: SI Lights - LR HRU | D41: Direct Expiry | E41: Check Expiry Date | H41: =IFERROR(IF($D41="Manual Review","",IF($G41="","",IF($D41="Direct Expiry",$G41,EDATE($G41,$F41)))),"Check Date") | I41: =IF($H41="","",IF(ISNUMBER($H41),$H41-TODAY(),"")) | J41: =IF($D41="Manual Review","Manual Review",IF($G41="","No Data",IF(NOT(ISNUMBER($H41)),"N/A",IF($H41<TODAY(),"Overdue",IF($H41<=TODAY()+30,"Due within 1 Month",IF($H41<=TODAY()+60,"Due within 2 Months","OK")))))) -> No Data
...

Sheet Dashboard
A1: LSA & FFA Fleet Dashboard
A2: Live snapshot as of today's date — reflects all 30 vessel slots on the Tracker sheet
A4: Total Tracked Items (All Vessels) | C4: Overdue (Red) | E4: Due within 1 Month (Amber) | G4: Due within 2 Months (Yellow) | I4: OK (Green) | K4: No Data / Manual Review
A5: =COUNTA(Tracker!C5:C3364) -> 3360 | C5: =COUNTIF(Tracker!J5:J3364,"Overdue") -> 13 | E5: =COUNTIF(Tracker!J5:J3364,"Due within 1 Month") -> 1 | G5: =COUNTIF(Tracker!J5:J3364,"Due within 2 Months") -> 0 | I5: =COUNTIF(Tracker!J5:J3364,"OK") -> 52 | K5: =COUNTIF(Tracker!J5:J3364,"No Data")+COUNTIF(Tracker!J5:J3364,"Manual Review")+COUNTIF(Tracker!J5:J3364,"N/A") -> 3294
A8: Due Soon by Vessel (2-Month & 1-Month Windows)
A9: Vessel | B9: Overdue (Red) | C9: Due in 1 Month (Amber) | D9: Due in 2 Months (Yellow) | E9: Total Due Soon
A10: =Vessels!B5 -> Vessel 01 | B10: =COUNTIFS(Tracker!A5:A3364,Vessels!B5,Tracker!J5:J3364,"Overdue") -> 13 | C10: =COUNTIFS(Tracker!A5:A3364,Vessels!B5,Tracker!J5:J3364,"Due within 1 Month") -> 1 | D10: =COUNTIFS(Tracker!A5:A3364,Vessels!B5,Tracker!J5:J3364,"Due within 2 Months") -> 0 | E10: =B10+C10+D10 -> 14
A11: =Vessels!B6 -> Vessel 02 | B11: =COUNTIFS(Tracker!A5:A3364,Vessels!B6,Tracker!J5:J3364,"Overdue") -> 0 | C11: =COUNTIFS(Tracker!A5:A3364,Vessels!B6,Tracker!J5:J3364,"Due within 1 Month") -> 0 | D11: =COUNTIFS(Tracker!A5:A3364,Vessels!B6,Tracker!J5:J3364,"Due within 2 Months") -> 0 | E11: =B11+C11+D11 -> 0
A12: =Vessels!B7 -> Vessel 03 | B12: =COUNTIFS(Tracker!A5:A3364,Vessels!B7,Tracker!J5:J3364,"Overdue") -> 0 | C12: =COUNTIFS(Tracker!A5:A3364,Vessels!B7,Tracker!J5:J3364,"Due within 1 Month") -> 0 | D12: =COUNTIFS(Tracker!A5:A3364,Vessels!B7,Tracker!J5:J3364,"Due within 2 Months") -> 0 | E12: =B12+C12+D12 -> 0
A13: =Vessels!B8 -> Vessel 04 | B13: =COUNTIFS(Tracker!A5:A3364,Vessels!B8,Tracker!J5:J3364,"Overdue") -> 0 | C13: =COUNTIFS(Tracker!A5:A3364,Vessels!B8,Tracker!J5:J3364,"Due within 1 Month") -> 0 | D13: =COUNTIFS(Tracker!A5:A3364,Vessels!B8,Tracker!J5:J3364,"Due within 2 Months") -> 0 | E13: =B13+C13+D13 -> 0
A14: =Vessels!B9 -> Vessel 05 | B14: =COUNTIFS(Tracker!A5:A3364,Vessels!B9,Tracker!J5:J3364,"Overdue") -> 0 | C14: =COUNTIFS(Tracker!A5:A3364,Vessels!B9,Tracker!J5:J3364,"Due within 1 Month") -> 0 | D14: =COUNTIFS(Tracker!A5:A3364,Vessels!B9,Tracker!J5:J3364,"Due within 2 Months") -> 0 | E14: =B14+C14+D14 -> 0
A15: =Vessels!B10 -> Vessel 06 | B15: =COUNTIFS(Tracker!A5:A3364,Vessels!B10,Tracker!J5:J3364,"Overdue") -> 0 | C15: =COUNTIFS(Tracker!A5:A3364,Vessels!B10,Tracker!J5:J3364,"Due within 1 Month") -> 0 | D15: =COUNTIFS(Tracker!A5:A3364,Vessels!B10,Tracker!J5:J3364,"Due within 2 Months") -> 0 | E15: =B15+C15+D15 -> 0
A16: =Vessels!B11 -> Vessel 07 | B16: =COUNTIFS(Tracker!A5:A3364,Vessels!B11,Tracker!J5:J3364,"Overdue") -> 0 | C16: =COUNTIFS(Tracker!A5:A3364,Vessels!B11,Tracker!J5:J3364,"Due within 1 Month") -> 0 | D16: =COUNTIFS(Tracker!A5:A3364,Vessels!B11,Tracker!J5:J3364,"Due within 2 Months") -> 0 | E16: =B16+C16+D16 -> 0
A17: =Vessels!B12 -> Vessel 08 | B17: =COUNTIFS(Tracker!A5:A3364,Vessels!B12,Tracker!J5:J3364,"Overdue") -> 0 | C17: =COUNTIFS(Tracker!A5:A3364,Vessels!B12,Tracker!J5:J3364,"Due within 1 Month") -> 0 | D17: =COUNTIFS(Tracker!A5:A3364,Vessels!B12,Tracker!J5:J3364,"Due within 2 Months") -> 0 | E17: =B17+C17+D17 -> 0
A18: =Vessels!B13 -> Vessel 09 | B18: =COUNTIFS(Tracker!A5:A3364,Vessels!B13,Tracker!J5:J3364,"Overdue") -> 0 | C18: =COUNTIFS(Tracker!A5:A3364,Vessels!B13,Tracker!J5:J3364,"Due within 1 Month") -> 0 | D18: =COUNTIFS(Tracker!A5:A3364,Vessels!B13,Tracker!J5:J3364,"Due within 2 Months") -> 0 | E18: =B18+C18+D18 -> 0
A19: =Vessels!B14 -> Vessel 10 | B19: =COUNTIFS(Tracker!A5:A3364,Vessels!B14,Tracker!J5:J3364,"Overdue") -> 0 | C19: =COUNTIFS(Tracker!A5:A3364,Vessels!B14,Tracker!J5:J3364,"Due within 1 Month") -> 0 | D19: =COUNTIFS(Tracker!A5:A3364,Vessels!B14,Tracker!J5:J3364,"Due within 2 Months") -> 0 | E19: =B19+C19+D19 -> 0
A20: =Vessels!B15 -> Vessel 11 | B20: =COUNTIFS(Tracker!A5:A3364,Vessels!B15,Tracker!J5:J3364,"Overdue") -> 0 | C20: =COUNTIFS(Tracker!A5:A3364,Vessels!B15,Tracker!J5:J3364,"Due within 1 Month") -> 0 | D20: =COUNTIFS(Tracker!A5:A3364,Vessels!B15,Tracker!J5:J3364,"Due within 2 Months") -> 0 | E20: =B20+C20+D20 -> 0
A21: =Vessels!B16 -> Vessel 12 | B21: =COUNTIFS(Tracker!A5:A3364,Vessels!B16,Tracker!J5:J3364,"Overdue") -> 0 | C21: =COUNTIFS(Tracker!A5:A3364,Vessels!B16,Tracker!J5:J3364,"Due within 1 Month") -> 0 | D21: =COUNTIFS(Tracker!A5:A3364,Vessels!B16,Tracker!J5:J3364,"Due within 2 Months") -> 0 | E21: =B21+C21+D21 -> 0
A22: =Vessels!B17 -> Vessel 13 | B22: =COUNTIFS(Tracker!A5:A3364,Vessels!B17,Tracker!J5:J3364,"Overdue") -> 0 | C22: =COUNTIFS(Tracker!A5:A3364,Vessels!B17,Tracker!J5:J3364,"Due within 1 Month") -> 0 | D22: =COUNTIFS(Tracker!A5:A3364,Vessels!B17,Tracker!J5:J3364,"Due within 2 Months") -> 0 | E22: =B22+C22+D22 -> 0
A23: =Vessels!B18 -> Vessel 14 | B23: =COUNTIFS(Tracker!A5:A3364,Vessels!B18,Tracker!J5:J3364,"Overdue") -> 0 | C23: =COUNTIFS(Tracker!A5:A3364,Vessels!B18,Tracker!J5:J3364,"Due within 1 Month") -> 0 | D23: =COUNTIFS(Tracker!A5:A3364,Vessels!B18,Tracker!J5:J3364,"Due within 2 Months") -> 0 | E23: =B23+C23+D23 -> 0
A24: =Vessels!B19 -> Vessel 15 | B24: =COUNTIFS(Tracker!A5:A3364,Vessels!B19,Tracker!J5:J3364,"Overdue") -> 0 | C24: =COUNTIFS(Tracker!A5:A3364,Vessels!B19,Tracker!J5:J3364,"Due within 1 Month") -> 0 | D24: =COUNTIFS(Tracker!A5:A3364,Vessels!B19,Tracker!J5:J3364,"Due within 2 Months") -> 0 | E24: =B24+C24+D24 -> 0
A25: =Vessels!B20 -> Vessel 16 | B25: =COUNTIFS(Tracker!A5:A3364,Vessels!B20,Tracker!J5:J3364,"Overdue") -> 0 | C25: =COUNTIFS(Tracker!A5:A3364,Vessels!B20,Tracker!J5:J3364,"Due within 1 Month") -> 0 | D25: =COUNTIFS(Tracker!A5:A3364,Vessels!B20,Tracker!J5:J3364,"Due within 2 Months") -> 0 | E25: =B25+C25+D25 -> 0
A26: =Vessels!B21 -> Vessel 17 | B26: =COUNTIFS(Tracker!A5:A3364,Vessels!B21,Tracker!J5:J3364,"Overdue") -> 0 | C26: =COUNTIFS(Tracker!A5:A3364,Vessels!B21,Tracker!J5:J3364,"Due within 1 Month") -> 0 | D26: =COUNTIFS(Tracker!A5:A3364,Vessels!B21,Tracker!J5:J3364,"Due within 2 Months") -> 0 | E26: =B26+C26+D26 -> 0
A27: =Vessels!B22 -> Vessel 18 | B27: =COUNTIFS(Tracker!A5:A3364,Vessels!B22,Tracker!J5:J3364,"Overdue") -> 0 | C27: =COUNTIFS(Tracker!A5:A3364,Vessels!B22,Tracker!J5:J3364,"Due within 1 Month") -> 0 | D27: =COUNTIFS(Tracker!A5:A3364,Vessels!B22,Tracker!J5:J3364,"Due within 2 Months") -> 0 | E27: =B27+C27+D27 -> 0
A28: =Vessels!B23 -> Vessel 19 | B28: =COUNTIFS(Tracker!A5:A3364,Vessels!B23,Tracker!J5:J3364,"Overdue") -> 0 | C28: =COUNTIFS(Tracker!A5:A3364,Vessels!B23,Tracker!J5:J3364,"Due within 1 Month") -> 0 | D28: =COUNTIFS(Tracker!A5:A3364,Vessels!B23,Tracker!J5:J3364,"Due within 2 Months") -> 0 | E28: =B28+C28+D28 -> 0
A29: =Vessels!B24 -> Vessel 20 | B29: =COUNTIFS(Tracker!A5:A3364,Vessels!B24,Tracker!J5:J3364,"Overdue") -> 0 | C29: =COUNTIFS(Tracker!A5:A3364,Vessels!B24,Tracker!J5:J3364,"Due within 1 Month") -> 0 | D29: =COUNTIFS(Tracker!A5:A3364,Vessels!B24,Tracker!J5:J3364,"Due within 2 Months") -> 0 | E29: =B29+C29+D29 -> 0
A30: =Vessels!B25 -> Vessel 21 | B30: =COUNTIFS(Tracker!A5:A3364,Vessels!B25,Tracker!J5:J3364,"Overdue") -> 0 | C30: =COUNTIFS(Tracker!A5:A3364,Vessels!B25,Tracker!J5:J3364,"Due within 1 Month") -> 0 | D30: =COUNTIFS(Tracker!A5:A3364,Vessels!B25,Tracker!J5:J3364,"Due within 2 Months") -> 0 | E30: =B30+C30+D30 -> 0
A31: =Vessels!B26 -> Vessel 22 | B31: =COUNTIFS(Tracker!A5:A3364,Vessels!B26,Tracker!J5:J3364,"Overdue") -> 0 | C31: =COUNTIFS(Tracker!A5:A3364,Vessels!B26,Tracker!J5:J3364,"Due within 1 Month") -> 0 | D31: =COUNTIFS(Tracker!A5:A3364,Vessels!B26,Tracker!J5:J3364,"Due within 2 Months") -> 0 | E31: =B31+C31+D31 -> 0
A32: =Vessels!B27 -> Vessel 23 | B32: =COUNTIFS(Tracker!A5:A3364,Vessels!B27,Tracker!J5:J3364,"Overdue") -> 0 | C32: =COUNTIFS(Tracker!A5:A3364,Vessels!B27,Tracker!J5:J3364,"Due within 1 Month") -> 0 | D32: =COUNTIFS(Tracker!A5:A3364,Vessels!B27,Tracker!J5:J3364,"Due within 2 Months") -> 0 | E32: =B32+C32+D32 -> 0
A33: =Vessels!B28 -> Vessel 24 | B33: =COUNTIFS(Tracker!A5:A3364,Vessels!B28,Tracker!J5:J3364,"Overdue") -> 0 | C33: =COUNTIFS(Tracker!A5:A3364,Vessels!B28,Tracker!J5:J3364,"Due within 1 Month") -> 0 | D33: =COUNTIFS(Tracker!A5:A3364,Vessels!B28,Tracker!J5:J3364,"Due within 2 Months") -> 0 | E33: =B33+C33+D33 -> 0
A34: =Vessels!B29 -> Vessel 25 | B34: =COUNTIFS(Tracker!A5:A3364,Vessels!B29,Tracker!J5:J3364,"Overdue") -> 0 | C34: =COUNTIFS(Tracker!A5:A3364,Vessels!B29,Tracker!J5:J3364,"Due within 1 Month") -> 0 | D34: =COUNTIFS(Tracker!A5:A3364,Vessels!B29,Tracker!J5:J3364,"Due within 2 Months") -> 0 | E34: =B34+C34+D34 -> 0
A35: =Vessels!B30 -> Vessel 26 | B35: =COUNTIFS(Tracker!A5:A3364,Vessels!B30,Tracker!J5:J3364,"Overdue") -> 0 | C35: =COUNTIFS(Tracker!A5:A3364,Vessels!B30,Tracker!J5:J3364,"Due within 1 Month") -> 0 | D35: =COUNTIFS(Tracker!A5:A3364,Vessels!B30,Tracker!J5:J3364,"Due within 2 Months") -> 0 | E35: =B35+C35+D35 -> 0
A36: =Vessels!B31 -> Vessel 27 | B36: =COUNTIFS(Tracker!A5:A3364,Vessels!B31,Tracker!J5:J3364,"Overdue") -> 0 | C36: =COUNTIFS(Tracker!A5:A3364,Vessels!B31,Tracker!J5:J3364,"Due within 1 Month") -> 0 | D36: =COUNTIFS(Tracker!A5:A3364,Vessels!B31,Tracker!J5:J3364,"Due within 2 Months") -> 0 | E36: =B36+C36+D36 -> 0
A37: =Vessels!B32 -> Vessel 28 | B37: =COUNTIFS(Tracker!A5:A3364,Vessels!B32,Tracker!J5:J3364,"Overdue") -> 0 | C37: =COUNTIFS(Tracker!A5:A3364,Vessels!B32,Tracker!J5:J3364,"Due within 1 Month") -> 0 | D37: =COUNTIFS(Tracker!A5:A3364,Vessels!B32,Tracker!J5:J3364,"Due within 2 Months") -> 0 | E37: =B37+C37+D37 -> 0
A38: =Vessels!B33 -> Vessel 29 | B38: =COUNTIFS(Tracker!A5:A3364,Vessels!B33,Tracker!J5:J3364,"Overdue") -> 0 | C38: =COUNTIFS(Tracker!A5:A3364,Vessels!B33,Tracker!J5:J3364,"Due within 1 Month") -> 0 | D38: =COUNTIFS(Tracker!A5:A3364,Vessels!B33,Tracker!J5:J3364,"Due within 2 Months") -> 0 | E38: =B38+C38+D38 -> 0
A39: =Vessels!B34 -> Vessel 30 | B39: =COUNTIFS(Tracker!A5:A3364,Vessels!B34,Tracker!J5:J3364,"Overdue") -> 0 | C39: =COUNTIFS(Tracker!A5:A3364,Vessels!B34,Tracker!J5:J3364,"Due within 1 Month") -> 0 | D39: =COUNTIFS(Tracker!A5:A3364,Vessels!B34,Tracker!J5:J3364,"Due within 2 Months") -> 0 | E39: =B39+C39+D39 -> 0
A42: Due Soon by Category (All Vessels)
A43: Category | B43: Overdue | C43: Due in 1 Month | D43: Due in 2 Months
A44: Life Saving Appliances | B44: =COUNTIFS(Tracker!B5:B3364,"Life Saving Appliances",Tracker!J5:J3364,"Overdue") -> 5 | C44: =COUNTIFS(Tracker!B5:B3364,"Life Saving Appliances",Tracker!J5:J3364,"Due within 1 Month") -> 0 | D44: =COUNTIFS(Tracker!B5:B3364,"Life Saving Appliances",Tracker!J5:J3364,"Due within 2 Months") -> 0
A45: Fire Fighting Appliances | B45: =COUNTIFS(Tracker!B5:B3364,"Fire Fighting Appliances",Tracker!J5:J3364,"Overdue") -> 4 | C45: =COUNTIFS(Tracker!B5:B3364,"Fire Fighting Appliances",Tracker!J5:J3364,"Due within 1 Month") -> 0 | D45: =COUNTIFS(Tracker!B5:B3364,"Fire Fighting Appliances",Tracker!J5:J3364,"Due within 2 Months") -> 0
...
